Workbook

Sheet Feedback
A1: Total Marks
A2: =A$14+(Features!A$8+'State Machine & Upd. Controller'!A$1+'State Machine & Upd. Controller'!A$7+'Gherkin Step Definitions'!A$1+'Gherkin Step Definitions'!A$5)*B70+A$36+A$40+A$44+A$48+A$52+A$56+B61-A$9 -> 92 | B2: /100 | C2: Member 1: | D2: Simon Wang
A3: =A$14+(Features!A$8+'State Machine & Upd. Controller'!A$1+'State Machine & Upd. Controller'!A$7+'Gherkin Step Definitions'!A$1+'Gherkin Step Definitions'!A$5)*B71+A$36+A$40+A$44+A$48+A$52+A$56+B62-A$9 -> 89 | B3: /100 | C3: Member 2: | D3: Benjamin Coriat
A4: =A$14+(Features!A$8+'State Machine & Upd. Controller'!A$1+'State Machine & Upd. Controller'!A$7+'Gherkin Step Definitions'!A$1+'Gherkin Step Definitions'!A$5)*B72+A$36+A$40+A$44+A$48+A$52+A$56+B63-A$9 -> 89 | B4: /100 | C4: Member 3: | D4: Jiahao Li
A5: =A$14+(Features!A$8+'State Machine & Upd. Controller'!A$1+'State Machine & Upd. Controller'!A$7+'Gherkin Step Definitions'!A$1+'Gherkin Step Definitions'!A$5)*B73+A$36+A$40+A$44+A$48+A$52+A$56+B64-A$9 -> 89 | B5: /100 | C5: Member 4: | D5: Noah Venturelli
A6: =A$14+(Features!A$8+'State Machine & Upd. Controller'!A$1+'State Machine & Upd. Controller'!A$7+'Gherkin Step Definitions'!A$1+'Gherkin Step Definitions'!A$5)*B74+A$36+A$40+A$44+A$48+A$52+A$56+B65-A$9 -> 89 | B6: /100 | C6: Member 5: | D6: Lazarus Sarghi
A7: =A$14+(Features!A$8+'State Machine & Upd. Controller'!A$1+'State Machine & Upd. Controller'!A$7+'Gherkin Step Definitions'!A$1+'Gherkin Step Definitions'!A$5)*B75+A$36+A$40+A$44+A$48+A$52+A$56+B66-A$9 -> 92 | B7: /100 | C7: Member 6: | D7: Aditya Shetty
A8: =A$14+(Features!A$8+'State Machine & Upd. Controller'!A$1+'State Machine & Upd. Controller'!A$7+'Gherkin Step Definitions'!A$1+'Gherkin Step Definitions'!A$5)*B76+A$36+A$40+A$44+A$48+A$52+A$56+B67-A$9 -> 89 | B8: /100 | C8: Member 7: | D8: George Zhou
B9: Late Penalty
A11: An entry in column C only applies if there is a deduction in column B.
A12: See other worksheets for further feedback.
A14: =ROUNDUP(10*B16/24.5,1) -> 10 | B14: /10 Correctness and completeness of state machine(s) specification in Umple (team mark)
A15: (see sample solution)
B16: =24.5+SUM(B17:B33) -> 24.5 | C16: /24.5 (points) missing or incorrect states, transitions, events, conditions, actions
B17: 0 | C17: Idle (-1)
B18: 0 | C18: AtEntranceNotFacingAisle (-1)
B19: 0 | C19: AtEntranceFacingAisle (-1)
B20: 0 | C20: AtCheeseWheel (-1)
B21: 0 | C21: Final (-1)
B22: 0 | C22: Idle: initialize(...) [shelfExists(...)] / { doInitialize(...); } -> AtEntranceNotFacingAisle (-2)
B23: 0 | C23: Idle: deactivate -> Final (-1)
C24: AtEntranceNotFacingAisle: treatPurchase -> AtEntranceNotFacingAisle (no deduction if missing)
B25: 0 | C25: AtEntranceNotFacingAisle: turnLeft / { doTurnLeft(); } -> AtEntranceFacingAisle (-1.5)
B26: 0 | C26: AtEntranceNotFacingAisle: goToShelf(...) [shelfExists(...)] / { doGoToShelf(...); } -> AtEntranceNotFacingAisle (-2)
B27: 0 | C27: AtEntranceNotFacingAisle: deactivate -> Final (-1)
B28: 0 | C28: AtEntranceFacingAisle: goToCheeseWheel(...) [isOnCurrentShelf(…)] / { doGoToCheeseWheel(…); } -> AtCheeseWheel (-2)
B29: 0 | C29: AtEntranceFacingAisle: turnRight / { doTurnRight(); } -> AtEntranceNotFacingAisle (-1.5)
B30: 0 | C30: AtCheeseWheel: treatCheeseWheel / { doTreatCheeseWheel(); } -> AtCheeseWheel (-1.5)
B31: 0 | C31: AtCheeseWheel: goToCheeseWheel(...) [isOnCurrentShelf(…)] / { doGoToCheeseWheel(…); } -> AtCheeseWheel (-2)
B32: 0 | C32: AtCheeseWheel: goToEntrance / { doGoToEntrance(); } -> AtEntranceFacingAisle (-1.5)
B33: 0 | C33: transitions for exceptions missing: more than one (-1); some (-2); many (-3); most (-4)
B34: Comments:
A36: =5+MIN(MAX(SUM(B37),-5),0) -> 5 | B36: /5 Correctness and completeness of Persistence layer (team mark)
B37: 0 | C37: persistence layer is missing (-5), major issue with persistence layer (-3), minor issue with persistence layer (-1)
B38: Comments:
A40: =3+MIN(MAX(SUM(B41),-3),0) -> 0 | B40: /3 Correctness of generated code (team mark)
B41: -3 | C41: generated code does not compile (-3), generated code has been manually updated (-2), incorrect package (-1)
B42: Comments: | C42: Persistence.ump line 64 calls a variable which doesn’t exist leading to compilation error
A44: =2+MIN(MAX(SUM(B45),-2),0) -> 1 | B44: /2 Correctness of project build and setup (team mark)
B45: -1 | C45: gradle project does not build and its folder structure is incorrect (-2), gradle project does not build but its folder structure is correct (-1), folder structure of grade project is incorrect (-0.5)
...

Sheet Features
A1: ACCEPTANCE TEST
A2: (see Gherkin specifications for Iteration 3)
A4: /100 | B4: Scenario | C4: nrTests | D4: nrFails
A5: =ROUND((C5-D5)/C5*100,0) -> 100 | B5: 1. AgingTreatment | C5: 44 | D5: 0
A6: =ROUND((C6-D6)/C6*100,0) -> 100 | B6: 2. RobotMovement | C6: 43 | D6: 0
A8: =ROUND(30*A9/100,1) -> 30 | B8: /30 Execution of acceptance tests
A9: =ROUND(SUM(A5:A6)/COUNT(A5:A6),2) -> 100 | B9: %

Sheet State Machine & Upd. Controller
A1: =5+MIN(MAX(SUM(A2:A4),-5),0) -> 4 | B1: /5 Documentation of state machine(s) and updated Controller (for all manually implemented methods)
A2: 0 | B2: more details not provided for manually implemented state machine methods: one (-0.5), two (-1), at least three (-1.5), most (-2)
A3: 0 | B3: more details not provided for public Controller methods: one (-0.5), two (-1), at least three (-1.5), most (-2)
A4: -1 | B4: @author not provided for private Controller methods: one or two (-0.5), at least three (-1)
A5: Comments:
A7: =10+MIN(MAX(SUM(A8:A9),-10),0) -> 10 | B7: /10 Implementation of state machine(s) and updated Controller
A8: 0 | B8: (-5) Controller queries the state of the state machine or performs actions based on a state
A9: 0 | B9: (-1) for each issue up to a maximum of 5 isssues
A10: Comments:

Sheet Gherkin Step Definitions
A1: =5+MIN(MAX(SUM(A2:A2),-5),0) -> 5 | B1: /5 Documentation of Gherkin step definitions (for all manually implemented methods)
A2: 0 | B2: @author not provided for step definition methods: one (-1), two (-2), at least three (-3), most (-4); all (-5)
A3: Comments:
A5: =15+MIN(MAX(SUM(A6:A9),-15),0) -> 12 | B5: /15 Implementation of Gherkin step definitions
A6: 0 | B6: (-3) step definitions for Given call the Controller instead of the Model (except when bringing a test object into the desired state)
A7: -3 | B7: (-3) step definitions for When do not call the Controller
A8: 0 | B8: (-3) step definitions for Then do not call the Model or do not contain assertions
A9: 0 | B9: (-1) for each issue up to a maximum of 6 isssues
A10: Comments: | B10: When step for RobotMovement (All) must directly call the statemachine
